Workbook

Sheet README
A1: Comprehensive Corporate Finance Evaluation of Infosys Ltd.
A6: Subject | B6: Corporate Finance using Excel
A7: Compay | B7: Infosys Ltd.
A9: ROLL NO | B9: GROUP MEMBERS NAME
A10: 065006 | B10: Aditi Agarwal
A11: 065008 | B11: Akshit Kansal
A12: 065010 | B12: Aman Malhi
A13: 065036 | B13: Mayank Jha
A14: 065040 | B14: Parv
A15: 065060 | B15: Awantika Kholia
A17: Sheet | B17: Description
A18: RawPrice_Daily | B18: 1.This sheet contains daily historical prices of Infosys and the Sensex over 10-year and 5-year periods. 2.It calculates daily percentage returns for both Infosys and the market, which are used for further analysis. 3.This data acts as the base input for beta calculation, volatility analysis, and valuation models in later sheets.
B20: 1.Stores weekly closing prices of Infosys and the Sensex to smooth out daily noise.
A22: RawPrice_Weekly | B22: 2.Calculates weekly returns, which are more stable for regression and beta estimation.
B24: 3.Provides a cleaner dataset for medium-term trend and market sensitivity analysis.
B28: 1.Contains monthly price data used to study long-term stock behaviour.
A29: RawPrice_Monthly | B29: 2.Monthly returns derived here support CAGR, long-term return, and valuation inputs.
B30: 3.Used especially for long-horizon beta and trend analysis.
B32: 1.Uses weekly or monthly returns to run a regression against Sensex returns.
A33: Beta_Calculations | B33: 2.Determines the stock’s beta, R² and other statistical outputs.
B34: 3.Provides the cost of equity input for WACC and valuation models.
A36: Income_Statement | B36: 1.Records historical revenues, expenses, and profits over multiple years. 2.Helps analyse profitability trends and operating performance. 3.Feeds into ratio analysis, forecasting, and valuation.
A38: Balance_Sheet | B38: 1.Contains yearly assets, liabilities, and equity data. 2.Helps evaluate financial structure, liquidity, and solvency. 3.Supports ratio calculations and working capital assessment.
A40: Cash_Flow_Statement | B40: 1.Shows operating, investing, and financing cash flows across years. 2.Helps determine free cash flow, which is key for valuation. 3.Indicates the company’s true cash-generating ability.
A42: Ratio_Analysis | B42: 1.Summarizes key profitability, liquidity, leverage, and efficiency ratios. 2.Helps interpret how the company’s financial performance is changing. 3.Connects raw financials to actionable insights and valuation inputs.
A44: WACC | B44: 1.Calculates the Weighted Average Cost of Capital using cost of equity and cost of debt. 2.Uses beta from earlier sheets to derive cost of equity. 3.Provides the discount rate for DCF and investment analysis.
A46: Investment_Analysis | B46: 1.Contains valuation models like DCF, NPV, IRR and scenario analysis. 2.Converts financial forecasts into an estimated fair value of the company. 3.Helps determine whether Infosys is a good investment opportunity.
A48: Dividend_Analysis | B48: 1.Tracks historical dividend payments and payout ratios. 2.Assesses dividend stability and growth patterns. 3.Supports dividend discount modelling for valuation.
A50: Working_Capital | B50: 1.Analyses receivables, payables, and inventory cycles. 2.Measures changes in short-term liquidity and operational efficiency. 3.Helps compute working-capital adjustments for free cash flow.
A52: Charts_Dashboard | B52: 1.Analyses receivables, payables, and inventory cycles. 2.Measures changes in short-term liquidity and operational efficiency. 3.Helps compute working-capital adjustments for free cash flow.
A54: DataSources_and_Checks | B54: 1.Lists all data origins, including market data and financial statements. 2.Contains error checks and validation formulas to ensure reliability. 3.Ensures data transparency and that the entire workbook is error-free.

Sheet RawPrice_Daily
A1: 10 Year | H1: 5 Year
A3: Date | B3: Infosys | C3: Sensex | D3: Infosys Return | E3: Sensex Return | H3: Date | I3: Infosys | J3: Sensex | K3: Infosys Return | L3: Sensex Return
A4: 42332 | B4: 1041 | C4: 25958.63 | D4: =LN(B5/B4) -> 0.011651359 | E4: =LN(C5/C4) -> 0.0065110739 | H4: 44160 | I4: 1116.2 | J4: 43828.1 | K4: =LN(I5/I4) -> -0.0022871504 | L4: =LN(J5/J4) -> 0.009800296
A5: 42334 | B5: 1053.2 | C5: 26128.2 | D5: =LN(B6/B5) -> 0.012361563 | E5: =LN(C6/C5) -> 0.0006684028 | H5: 44161 | I5: 1113.65 | J5: 44259.74 | K5: =LN(I6/I5) -> -0.011832854 | L5: =LN(J6/J5) -> -0.0024888752
A6: 42335 | B6: 1066.3 | C6: 26145.67 | D6: =LN(B7/B6) -> 0.020559954 | E6: =LN(C7/C6) -> 0.00090757776 | H6: 44162 | I6: 1100.55 | J6: 44149.72 | K6: =LN(I7/I6) -> 0.032803013 | L6: =LN(J7/J6) -> 0.011389551
A7: 42338 | B7: 1088.45 | C7: 26169.41 | D7: =LN(B8/B7) -> -0.010900297 | E7: =LN(C8/C7) -> -0.0019721828 | H7: 44166 | I7: 1137.25 | J7: 44655.44 | K7: =LN(I8/I7) -> 0.0033358237 | L7: =LN(J8/J7) -> -0.00083787486
A8: 42339 | B8: 1076.65 | C8: 26117.85 | D8: =LN(B9/B8) -> -0.015396799 | E8: =LN(C9/C8) -> -0.0088927557 | H8: 44167 | I8: 1141.05 | J8: 44618.04 | K8: =LN(I9/I8) -> -0.012789026 | L8: =LN(J9/J8) -> 0.00032739243
A9: 42340 | B9: 1060.2 | C9: 25886.62 | D9: =LN(B10/B9) -> -0.0039693843 | E9: =LN(C10/C9) -> -0.0096463165 | H9: 44168 | I9: 1126.55 | J9: 44632.65 | K9: =LN(I10/I9) -> 0.0071643682 | L9: =LN(J10/J9) -> 0.0099630529
A10: 42341 | B10: 1056 | C10: 25638.11 | D10: =LN(B11/B10) -> -0.0077954573 | E10: =LN(C11/C10) -> -0.0042213765 | H10: 44169 | I10: 1134.65 | J10: 45079.55 | K10: =LN(I11/I10) -> 0.008250365 | L10: =LN(J11/J10) -> 0.0076772747
A11: 42342 | B11: 1047.8 | C11: 25530.11 | D11: =LN(B12/B11) -> -0.0018627761 | E11: =LN(C12/C11) -> -0.0086459271 | H11: 44172 | I11: 1144.05 | J11: 45426.97 | K11: =LN(I12/I11) -> 0.0085295787 | L11: =LN(J12/J11) -> 0.0039883404
A12: 42345 | B12: 1045.85 | C12: 25310.33 | D12: =LN(B13/B12) -> -0.00086091454 | E12: =LN(C13/C12) -> -0.010895827 | H12: 44173 | I12: 1153.85 | J12: 45608.51 | K12: =LN(I13/I12) -> 0.018291622 | L12: =LN(J13/J12) -> 0.010794547
A13: 42346 | B13: 1044.95 | C13: 25036.05 | D13: =LN(B14/B13) -> -0.015041502 | E13: =LN(C14/C13) -> 0.0086012465 | H13: 44174 | I13: 1175.15 | J13: 46103.5 | K13: =LN(I14/I13) -> -0.0065310885 | L13: =LN(J14/J13) -> -0.003120027
A14: 42347 | B14: 1029.35 | C14: 25252.32 | D14: =LN(B15/B14) -> 0.016428167 | E14: =LN(C15/C14) -> -0.0082665852 | H14: 44175 | I14: 1167.5 | J14: 45959.88 | K14: =LN(I15/I14) -> -0.0038188457 | L14: =LN(J15/J14) -> 0.0030226327
A15: 42348 | B15: 1046.4 | C15: 25044.43 | D15: =LN(B16/B15) -> 0.0056700569 | E15: =LN(C16/C15) -> 0.0042203654 | H15: 44176 | I15: 1163.05 | J15: 46099.01 | K15: =LN(I16/I15) -> 0.0012888814 | L15: =LN(J16/J15) -> 0.0033447973
... A1242: 44159 | B1242: 1139.15 | C1242: 43828.1 | D1242: =LN(B1243/B1242) -> -0.020352311 | E1242: =LN(C1243/C1242) -> 0.009800296 | H1242: 45985 | I1242: 1549.4 | J1242: 84900.71 | K1242: =LN(I1243/I1242) -> -0.012600024 | L1242: =LN(J1243/J1242) -> -0.0037017473
A1243: 44160 | B1243: 1116.2 | C1243: 44259.74 | D1243: =LN(B1244/B1243) -> -0.0022871504 | E1243: =LN(C1244/C1243) -> -0.0024888752 | H1243: 45986 | I1243: 1530 | J1243: 84587.01
A1244: 44161 | B1244: 1113.65 | C1244: 44149.72 | D1244: =LN(B1245/B1244) -> -0.011832854 | E1244: =LN(C1245/C1244) -> 0.011389551
A1245: 44162 | B1245: 1100.55 | C1245: 44655.44 | D1245: =LN(B1246/B1245) -> 0.032803013 | E1245: =LN(C1246/C1245) -> -0.00083787486
A1246: 44166 | B1246: 1137.25 | C1246: 44618.04 | D1246: =LN(B1247/B1246) -> 0.0033358237 | E1246: =LN(C1247/C1246) -> 0.00032739243
A1247: 44167 | B1247: 1141.05 | C1247: 44632.65 | D1247: =LN(B1248/B1247) -> -0.012789026 | E1247: =LN(C1248/C1247) -> 0.0099630529
A1248: 44168 | B1248: 1126.55 | C1248: 45079.55 | D1248: =LN(B1249/B1248) -> 0.0071643682 | E1248: =LN(C1249/C1248) -> 0.0076772747
A1249: 44169 | B1249: 1134.65 | C1249: 45426.97 | D1249: =LN(B1250/B1249) -> 0.008250365 | E1249: =LN(C1250/C1249) -> 0.0039883404
A1250: 44172 | B1250: 1144.05 | C1250: 45608.51 | D1250: =LN(B1251/B1250) -> 0.0085295787 | E1250: =LN(C1251/C1250) -> 0.010794547
A1251: 44173 | B1251: 1153.85 | C1251: 46103.5 | D1251: =LN(B1252/B1251) -> 0.018291622 | E1251: =LN(C1252/C1251) -> -0.003120027
A1252: 44174 | B1252: 1175.15 | C1252: 45959.88 | D1252: =LN(B1253/B1252) -> -0.0065310885 | E1252: =LN(C1253/C1252) -> 0.0030226327
A1253: 44175 | B1253: 1167.5 | C1253: 46099.01 | D1253: =LN(B1254/B1253) -> -0.0038188457 | E1253: =LN(C1254/C1253) -> 0.0033447973
A1254: 44176 | B1254: 1163.05 | C1254: 46253.46 | D1254: =LN(B1255/B1254) -> 0.0012888814 | E1254: =LN(C1255/C1254) -> 0.00020990821
A1255: 44179 | B1255: 1164.55 | C1255: 46263.17 | D1255: =LN(B1256/B1255) -> -0.0087540178 | E1255: =LN(C1256/C1255) -> 0.0086795252
... A2478: 45980 | B2478: 1541.25 | C2478: 84900.71 | D2478: =LN(B2479/B2478) -> -0.0029239787 | E2478: =LN(C2479/C2478) -> -0.0037017473
A2479: 45981 | B2479: 1536.75 | C2479: 84587.01

Sheet RawPrice_Weekly
A1: 10 Year | H1: 5 Year
A3: Date | B3: Infosys | C3: Sensex | D3: Infosys Return | E3: Sensex Return | H3: Date | I3: Infosys | J3: Sensex | K3: Infosys Return | L3: Sensex Return
A4: 11-27-2015 | B4: 533.17 | C4: 26128.2 | D4: =LN(B5/B4) -> -0.016337699 | E4: =LN(C5/C4) -> -0.018935274 | H4: 11-27-2020 | I4: 1100 | J4: 41464.61 | K4: =LN(I5/I4) -> 0.031014054 | L4: =LN(J5/J4) -> 0.0032531441
A5: 42106 | B5: 524.53 | C5: 25638.11 | D5: =LN(B6/B5) -> 0.0035587565 | E5: =LN(C6/C5) -> -0.023428469 | H5: 43933 | I5: 1134.65 | J5: 41599.72 | K5: =LN(I6/I5) -> 0.024850594 | L5: =LN(J6/J5) -> 0.0082746209
A6: 42320 | B6: 526.4 | C6: 25044.43 | D6: =LN(B7/B6) -> 0.028429413 | E6: =LN(C7/C6) -> 0.018780446 | H6: 44147 | I6: 1163.2 | J6: 41945.37 | K6: =LN(I7/I6) -> 0.022610398 | L6: =LN(J7/J6) -> -0.007950873
A7: 12-18-2015 | B7: 541.58 | C7: 25519.22 | D7: =LN(B8/B7) -> 0.012094665 | E7: =LN(C8/C7) -> 0.012441861 | H7: 12-18-2020 | I7: 1189.8 | J7: 41613.19 | K7: =LN(I8/I7) -> 0.038135586 | L7: =LN(J8/J7) -> -0.046171435
A8: 12-24-2015 | B8: 548.17 | C8: 25838.71 | D8: =LN(B9/B8) -> 0.008103242 | E8: =LN(C9/C8) -> 0.012392175 | H8: 12-24-2020 | I8: 1236.05 | J8: 39735.53 | K8: =LN(I9/I8) -> 0.019547989 | L8: =LN(J9/J8) -> 0.034780102
A9: 42370 | B9: 552.63 | C9: 26160.9 | D9: =LN(B10/B9) -> -0.038703322 | E9: =LN(C10/C9) -> -0.048020361 | H9: 44197 | I9: 1260.45 | J9: 41141.85 | K9: =LN(I10/I9) -> 0.040160107 | L9: =LN(J10/J9) -> 0.0028128799
A10: 42583 | B10: 531.65 | C10: 24934.33 | D10: =LN(B11/B10) -> 0.06956326 | E10: =LN(C11/C10) -> -0.019409239 | H10: 44409 | I10: 1312.1 | J10: 41257.74 | K10: =LN(I11/I10) -> 0.024727931 | L10: =LN(J11/J10) -> -0.002125981
A11: 1-15-2016 | B11: 569.95 | C11: 24455.04 | D11: =LN(B12/B11) -> -0.0031983719 | E11: =LN(C12/C11) -> -0.00079278885 | H11: 1-15-2021 | I11: 1344.95 | J11: 41170.12 | K11: =LN(I12/I11) -> -0.0030530964 | L11: =LN(J12/J11) -> -0.072333614
A12: 1-22-2016 | B12: 568.13 | C12: 24435.66 | D12: =LN(B13/B12) -> 0.024893079 | E12: =LN(C13/C12) -> 0.017646461 | H12: 1-22-2021 | I12: 1340.85 | J12: 38297.29 | K12: =LN(I13/I12) -> -0.078958784 | L12: =LN(J13/J12) -> -0.018997088
A13: 1-29-2016 | B13: 582.45 | C13: 24870.69 | D13: =LN(B14/B13) -> 0.0083775494 | E13: =LN(C14/C13) -> -0.010253959 | H13: 1-29-2021 | I13: 1239.05 | J13: 37576.62 | K13: =LN(I14/I13) -> 0.026324121 | L13: =LN(J14/J13) -> -0.096982617
A14: 42492 | B14: 587.35 | C14: 24616.97 | D14: =LN(B15/B14) -> -0.041222886 | E14: =LN(C15/C14) -> -0.068545487 | H14: 44318 | I14: 1272.1 | J14: 34103.48 | K14: =LN(I15/I14) -> 0.029205376 | L14: =LN(J15/J14) -> -0.13100731
A15: 2-19-2016 | B15: 563.63 | C15: 22986.12 | D15: =LN(B16/B15) -> -0.0054260458 | E15: =LN(C16/C15) -> 0.030970494 | H15: 44532 | I15: 1309.8 | J15: 29915.96 | K15: =LN(I16/I15) -> -0.014224991 | L15: =LN(J16/J15) -> -0.0033607062
A16: 2-26-2016 | B16: 560.58 | C16: 23709.15 | D16: =LN(B17/B16) -> 0.043203829 | E16: =LN(C17/C16) -> -0.023680541 | H16: 2-19-2021 | I16: 1291.3 | J16: 29815.59 | K16: =LN(I17/I16) -> -0.02986939 | L16: =LN(J17/J16) -> -0.077543591
A17: 42463 | B17: 585.33 | C17: 23154.3 | D17: =LN(B18/B17) -> -0.023911308 | E17: =LN(C18/C17) -> 0.062453583 | H17: 2-26-2021 | I17: 1253.3 | J17: 27590.95 | K17: =LN(I18/I17) -> 0.049348534 | L17: =LN(J18/J17) -> 0.12163521
A18: 42677 | B18: 571.5 | C18: 24646.48 | D18: =LN(B19/B18) -> 0.043149991 | E18: =LN(C19/C18) -> 0.0028972275 | H18: 44319 | I18: 1316.7 | J18: 31159.62 | K18: =LN(I19/I18) -> 0.043216028 | L18: =LN(J19/J18) -> 0.013677069
A19: 3-18-2016 | B19: 596.7 | C19: 24717.99 | D19: =LN(B20/B19) -> 0.011994147 | E19: =LN(C20/C19) -> 0.0094523172 | H19: 44533 | I19: 1374.85 | J19: 31588.72 | K19: =LN(I20/I19) -> -0.022359627 | L19: =LN(J20/J19) -> -0.0083127267
A20: 3-23-2016 | B20: 603.9 | C20: 24952.74 | D20: =LN(B21/B20) -> -0.0019392861 | E20: =LN(C21/C20) -> 0.015304244 | H20: 3-19-2021 | I20: 1344.45 | J20: 31327.22 | K20: =LN(I21/I20) -> -0.006155243 | L20: =LN(J21/J20) -> 0.073533181
A21: 42373 | B21: 602.73 | C21: 25337.56 | D21: =LN(B22/B21) -> -0.033488002 | E21: =LN(C22/C21) -> -0.0026842046 | H21: 3-26-2021 | I21: 1336.2 | J21: 33717.62 | K21: =LN(I22/I21) -> 0.036014769 | L21: =LN(J22/J21) -> -0.063513075
A22: 42586 | B22: 582.88 | C22: 25269.64 | D22: =LN(B23/B22) -> 0.0059355476 | E22: =LN(C23/C22) -> -0.023860102 | H22: 44200 | I22: 1385.2 | J22: 31642.7 | K22: =LN(I23/I22) -> 0.039527481 | L22: =LN(J23/J22) -> -0.017372648
A23: 4-13-2016 | B23: 586.35 | C23: 24673.84 | D23: =LN(B24/B23) -> 0.032352358 | E23: =LN(C24/C23) -> 0.037893155 | H23: 44443 | I23: 1441.05 | J23: 31097.73 | K23: =LN(I24/I23) -> -0.062493495 | L23: =LN(J24/J23) -> -0.013765404
A24: 4-22-2016 | B24: 605.63 | C24: 25626.75 | D24: =LN(B25/B24) -> -0.0026122626 | E24: =LN(C25/C24) -> 0.0082149671 | H24: 4-16-2021 | I24: 1353.75 | J24: 30672.59 | K24: =LN(I25/I24) -> -0.014846508 | L24: =LN(J25/J24) -> 0.055532552
A25: 4-29-2016 | B25: 604.05 | C25: 25838.14 | D25: =LN(B26/B25) -> -0.02226406 | E25: =LN(C26/C25) -> -0.0090007831 | H25: 4-23-2021 | I25: 1333.8 | J25: 32424.1 | K25: =LN(I26/I25) -> 0.015289623 | L25: =LN(J26/J25) -> 0.0558713
A26: 42526 | B26: 590.75 | C26: 25606.62 | D26: =LN(B27/B26) -> 0.021568511 | E26: =LN(C27/C26) -> -0.014876604 | H26: 4-30-2021 | I26: 1354.35 | J26: 34287.24 | K26: =LN(I27/I26) -> -0.0013299348 | L26: =LN(J27/J26) -> -0.014878015
A27: 5-13-2016 | B27: 603.63 | C27: 25228.5 | D27: =LN(B28/B27) -> -0.004699327 | E27: =LN(C28/C27) -> 0.010295041 | H27: 44382 | I27: 1352.55 | J27: 33780.89 | K27: =LN(I28/I27) -> -0.027090962 | L27: =LN(J28/J27) -> 0.02775842
A28: 5-20-2016 | B28: 600.8 | C28: 25489.57 | D28: =LN(B29/B28) -> 0.037487547 | E28: =LN(C29/C28) -> -0.0073898572 | H28: 5-14-2021 | I28: 1316.4 | J28: 34731.73 | K28: =LN(I29/I28) -> 0.028531644 | L28: =LN(J29/J28) -> 0.012575878
A29: 5-27-2016 | B29: 623.75 | C29: 25301.9 | D29: =LN(B30/B29) -> 0.015431423 | E29: =LN(C30/C29) -> 0.052044734 | H29: 5-21-2021 | I29: 1354.5 | J29: 35171.27 | K29: =LN(I30/I29) -> 0.036640507 | L29: =LN(J30/J29) -> 0.023884205
A30: 42435 | B30: 633.45 | C30: 26653.6 | D30: =LN(B31/B30) -> -0.070550188 | E30: =LN(C31/C30) -> 0.007081971 | H30: 5-28-2021 | I30: 1405.05 | J30: 36021.42 | K30: =LN(I31/I30) -> -0.013903546 | L30: =LN(J31/J30) -> 0.015779549
A31: 42649 | B31: 590.3 | C31: 26843.03 | D31: =LN(B32/B31) -> -0.00093216396 | E31: =LN(C32/C31) -> -0.0077518985 | H31: 44292 | I31: 1385.65 | J31: 36594.33 | K31: =LN(I32/I31) -> 0.043253993 | L31: =LN(J32/J31) -> 0.011568779
A32: 6-17-2016 | B32: 589.75 | C32: 26635.75 | D32: =LN(B33/B32) -> 0.012687297 | E32: =LN(C33/C32) -> -0.00036949656 | H32: 44506 | I32: 1446.9 | J32: 37020.14 | K32: =LN(I33/I32) -> 0.038239355 | L32: =LN(J33/J32) -> 0.029510436
A33: 6-24-2016 | B33: 597.28 | C33: 26625.91 | D33: =LN(B34/B33) -> -0.018724987 | E33: =LN(C34/C33) -> -0.0086075379 | H33: 6-18-2021 | I33: 1503.3 | J33: 38128.9 | K33: =LN(I34/I33) -> 0.046084515 | L33: =LN(J34/J33) -> -0.013785246
A34: 42376 | B34: 586.2 | C34: 26397.71 | D34: =LN(B35/B34) -> -0.012185854 | E34: =LN(C35/C34) -> 0.027912288 | H34: 6-25-2021 | I34: 1574.2 | J34: 37606.89 | K34: =LN(I35/I34) -> -0.004073844 | L34: =LN(J35/J34) -> 0.011465944
A35: 42589 | B35: 579.1 | C35: 27144.91 | D35: =LN(B36/B35) -> -0.076818761 | E35: =LN(C36/C35) -> -0.00066369633 | H35: 44234 | I35: 1567.8 | J35: 38040.57 | K35: =LN(I36/I35) -> -0.0031302929 | L35: =LN(J36/J35) -> -0.0043001777
A36: 7-15-2016 | B36: 536.28 | C36: 27126.9 | D36: =LN(B37/B36) -> -9.3239224e-05 | E36: =LN(C37/C36) -> 0.025822254 | H36: 44446 | I36: 1562.9 | J36: 37877.34 | K36: =LN(I37/I36) -> -0.004778177 | L36: =LN(J37/J36) -> 0.014608174
A37: 7-22-2016 | B37: 536.23 | C37: 27836.5 | D37: =LN(B38/B37) -> 0.0012859341 | E37: =LN(C38/C37) -> -0.0011955485 | H37: 7-16-2021 | I37: 1555.45 | J37: 38434.72 | K37: =LN(I38/I37) -> 0.022252102 | L37: =LN(J38/J37) -> 0.026511517
A38: 7-29-2016 | B38: 536.92 | C38: 27803.24 | D38: =LN(B39/B38) -> -0.0054532687 | E38: =LN(C39/C38) -> 0.0089023793 | H38: 7-23-2021 | I38: 1590.45 | J38: 39467.31 | K38: =LN(I39/I38) -> 0.012527695 | L38: =LN(J39/J38) -> -0.028531001
A39: 42498 | B39: 534 | C39: 28051.86 | D39: =LN(B40/B39) -> -0.0051066497 | E39: =LN(C40/C39) -> 0.00094387682 | H39: 7-30-2021 | I39: 1610.5 | J39: 38357.18 | K39: =LN(I40/I39) -> 0.024351803 | L39: =LN(J40/J39) -> 0.012883454
A40: 42712 | B40: 531.28 | C40: 28078.35 | D40: =LN(B41/B40) -> -0.039604765 | E40: =LN(C41/C40) -> 0.0026337918 | H40: 44355 | I40: 1650.2 | J40: 38854.55 | K40: =LN(I41/I40) -> 0.036882601 | L40: =LN(J41/J40) -> -0.00022470936
A41: 8-19-2016 | B41: 510.65 | C41: 28152.4 | D41: =LN(B42/B41) -> -0.0010188288 | E41: =LN(C42/C41) -> -0.0026818727 | H41: 8-13-2021 | I41: 1712.2 | J41: 38845.82 | K41: =LN(I42/I41) -> 0.012046065 | L41: =LN(J42/J41) -> -0.038233028
...

Sheet RawPrice_Monthly
A1: 10 Year | I1: 5 Year | R1: Standard Geometric CAGR Method
A3: Date | B3: Infosys | C3: Sensex | D3: Infosys Return | E3: Sensex Return | H3: Date | I3: Infosys | J3: Sensex | K3: Infosys Return | L3: Sensex Return | M3: Risk Free Rate | N3: Market Risk Premium (MRP) | P3: Sensex Return | Q3: 1+r | R3: Cummulative Market Return | S3: N=60 so N/12 | T3: Market Growth Rate
A4: 42309 | B4: 1088.45 | C4: 26145.67 | D4: =LN(B5/B4) -> 0.014683346 | E4: =LN(C5/C4) -> -0.0010764744 | H4: 44136 | I4: 1100.55 | J4: 44149.72 | K4: =LN(I5/I4) -> 0.13200258 | L4: =LN(J5/J4) -> 0.078420335 | M4: 0.0653 | N4: =L4-M4 -> 0.013120335 | P4: 0.078420335 | Q4: =1+P4 -> 1.0784203 | R4: =PRODUCT(Q4:Q63) -> 1.8390747 | S4: =12/60 -> 0.2 | T4: =(R4)^S4-1 -> 0.12958749
A5: 42339 | B5: 1104.55 | C5: 26117.54 | D5: =LN(B6/B5) -> 0.053154311 | E5: =LN(C6/C5) -> -0.048917118 | H5: 44166 | I5: 1255.85 | J5: 47751.33 | K5: =LN(I6/I5) -> -0.012983552 | L5: =LN(J6/J5) -> -0.03117235 | M5: 0.0653 | N5: =L5-M5 -> -0.09647235 | P5: -0.03117235 | Q5: =1+P5 -> 0.96882765
A6: 42370 | B6: 1164.85 | C6: 24870.69 | D6: =LN(B7/B6) -> -0.072165074 | E6: =LN(C7/C6) -> -0.078108833 | H6: 44197 | I6: 1239.65 | J6: 46285.77 | K6: =LN(I7/I6) -> 0.010192705 | L6: =LN(J7/J6) -> 0.059024261 | M6: 0.0653 | N6: =L6-M6 -> -0.0062757393 | P6: 0.059024261 | Q6: =1+P6 -> 1.0590243
A7: 42401 | B7: 1083.75 | C7: 23002 | D7: =LN(B8/B7) -> 0.11674187 | E7: =LN(C8/C7) -> 0.096876405 | H7: 44228 | I7: 1252.35 | J7: 49099.99 | K7: =LN(I8/I7) -> 0.088145268 | L7: =LN(J8/J7) -> 0.0082986698 | M7: 0.0653 | N7: =L7-M7 -> -0.05700133 | P7: 0.0082986698 | Q7: =1+P7 -> 1.0082987
A8: 42430 | B8: 1217.95 | C8: 25341.86 | D8: =LN(B9/B8) -> -0.0058465252 | E8: =LN(C9/C8) -> 0.010393338 | H8: 44256 | I8: 1367.75 | J8: 49509.15 | K8: =LN(I9/I8) -> -0.010177737 | L8: =LN(J9/J8) -> -0.014788729 | M8: 0.0653 | N8: =L8-M8 -> -0.080088729 | P8: -0.014788729 | Q8: =1+P8 -> 0.98521127
A9: 42461 | B9: 1210.85 | C9: 25606.62 | D9: =LN(B10/B9) -> 0.031700952 | E9: =LN(C10/C9) -> 0.040611933 | H9: 44287 | I9: 1353.9 | J9: 48782.36 | K9: =LN(I10/I9) -> 0.028936888 | L9: =LN(J10/J9) -> 0.062671145 | M9: 0.0653 | N9: =L9-M9 -> -0.0026288547 | P9: 0.062671145 | Q9: =1+P9 -> 1.0626711
A10: 42491 | B10: 1249.85 | C10: 26667.96 | D10: =LN(B11/B10) -> -0.065378975 | E10: =LN(C11/C10) -> 0.012363651 | H10: 44317 | I10: 1393.65 | J10: 51937.44 | K10: =LN(I11/I10) -> 0.12628947 | L10: =LN(J11/J10) -> 0.010443865 | M10: 0.0653 | N10: =L10-M10 -> -0.054856135 | P10: 0.010443865 | Q10: =1+P10 -> 1.0104439
A11: 42522 | B11: 1170.75 | C11: 26999.72 | D11: =LN(B12/B11) -> -0.086301129 | E11: =LN(C12/C11) -> 0.038228444 | H11: 44348 | I11: 1581.25 | J11: 52482.71 | K11: =LN(I12/I11) -> 0.018173773 | L11: =LN(J12/J11) -> 0.0019821163 | M11: 0.0653 | N11: =L11-M11 -> -0.063317884 | P11: 0.0019821163 | Q11: =1+P11 -> 1.0019821
A12: 42552 | B12: 1073.95 | C12: 28051.86 | D12: =LN(B13/B12) -> -0.035204393 | E12: =LN(C13/C12) -> 0.014169492 | H12: 44378 | I12: 1610.25 | J12: 52586.84 | K12: =LN(I13/I12) -> 0.056677006 | L12: =LN(J13/J12) -> 0.090229765 | M12: 0.0653 | N12: =L12-M12 -> 0.024929765 | P12: 0.090229765 | Q12: =1+P12 -> 1.0902298
A13: 42583 | B13: 1036.8 | C13: 28452.17 | D13: =LN(B14/B13) -> 0.0012530726 | E13: =LN(C14/C13) -> -0.02081856 | H13: 44409 | I13: 1704.15 | J13: 57552.39 | K13: =LN(I14/I13) -> -0.01701451 | L13: =LN(J14/J13) -> 0.026981185 | M13: 0.0653 | N13: =L13-M13 -> -0.038318815 | P13: 0.026981185 | Q13: =1+P13 -> 1.0269812
A14: 42614 | B14: 1038.1 | C14: 27865.96 | D14: =LN(B15/B14) -> -0.034895239 | E14: =LN(C15/C14) -> 0.0023030265 | H14: 44440 | I14: 1675.4 | J14: 59126.36 | K14: =LN(I15/I14) -> -0.0040669913 | L14: =LN(J15/J14) -> 0.0030493139 | M14: 0.0653 | N14: =L14-M14 -> -0.062250686 | P14: 0.0030493139 | Q14: =1+P14 -> 1.0030493
A15: 42644 | B15: 1002.5 | C15: 27930.21 | D15: =LN(B16/B15) -> -0.027353256 | E15: =LN(C16/C15) -> -0.046814313 | H15: 44470 | I15: 1668.6 | J15: 59306.93 | K15: =LN(I16/I15) -> 0.027107378 | L15: =LN(J16/J15) -> -0.038537472 | M15: 0.0653 | N15: =L15-M15 -> -0.10383747 | P15: -0.038537472 | Q15: =1+P15 -> 0.96146253
A16: 42675 | B16: 975.45 | C16: 26652.81 | D16: =LN(B17/B16) -> 0.035499536 | E16: =LN(C17/C16) -> -0.00098912775 | H16: 44501 | I16: 1714.45 | J16: 57064.87 | K16: =LN(I17/I16) -> 0.097299297 | L16: =LN(J17/J16) -> 0.020620979 | M16: 0.0653 | N16: =L16-M16 -> -0.044679021 | P16: 0.020620979 | Q16: =1+P16 -> 1.020621
... A63: 44105 | B63: 1060.6 | C63: 39614.07 | D63: =LN(B64/B63) -> 0.036975269 | E63: =LN(C64/C63) -> 0.10840223 | H63: 45931 | I63: 1482.5 | J63: 83938.71 | K63: =LN(I64/I63) -> 0.031537884 | L63: =LN(J64/J63) -> 0.0076938191 | M63: 0.0653 | N63: =L63-M63 -> -0.057606181 | P63: 0.0076938191 | Q63: =1+P63 -> 1.0076938
A64: 44136 | B64: 1100.55 | C64: 44149.72 | D64: =LN(B65/B64) -> 0.13200258 | E64: =LN(C65/C64) -> 0.078420335 | H64: 45962 | I64: 1530 | J64: 84587.01
A65: 44166 | B65: 1255.85 | C65: 47751.33 | D65: =LN(B66/B65) -> -0.012983552 | E65: =LN(C66/C65) -> -0.03117235 | M65: Final Market Risk Premium | N65: =AVERAGE(N4:N63) -> -0.054463431
A66: 44197 | B66: 1239.65 | C66: 46285.77 | D66: =LN(B67/B66) -> 0.010192705 | E66: =LN(C67/C66) -> 0.059024261
A67: 44228 | B67: 1252.35 | C67: 49099.99 | D67: =LN(B68/B67) -> 0.088145268 | E67: =LN(C68/C67) -> 0.0082986698
A68: 44256 | B68: 1367.75 | C68: 49509.15 | D68: =LN(B69/B68) -> -0.010177737 | E68: =LN(C69/C68) -> -0.014788729 | M68: Usually this method is used for 20-30 years of data but since we have only 5 years data, we get a negative MRP.
A69: 44287 | B69: 1353.9 | C69: 48782.36 | D69: =LN(B70/B69) -> 0.028936888 | E69: =LN(C70/C69) -> 0.062671145 | M69: So, we proceeded with the CAGR method to estimate Return of Market
A70: 44317 | B70: 1393.65 | C70: 51937.44 | D70: =LN(B71/B70) -> 0.12628947 | E70: =LN(C71/C70) -> 0.010443865
A71: 44348 | B71: 1581.25 | C71: 52482.71 | D71: =LN(B72/B71) -> 0.018173773 | E71: =LN(C72/C71) -> 0.0019821163
A72: 44378 | B72: 1610.25 | C72: 52586.84 | D72: =LN(B73/B72) -> 0.056677006 | E72: =LN(C73/C72) -> 0.090229765
A73: 44409 | B73: 1704.15 | C73: 57552.39 | D73: =LN(B74/B73) -> -0.01701451 | E73: =LN(C74/C73) -> 0.026981185
A74: 44440 | B74: 1675.4 | C74: 59126.36 | D74: =LN(B75/B74) -> -0.0040669913 | E74: =LN(C75/C74) -> 0.0030493139
A75: 44470 | B75: 1668.6 | C75: 59306.93 | D75: =LN(B76/B75) -> 0.027107378 | E75: =LN(C76/C75) -> -0.038537472
A76: 44501 | B76: 1714.45 | C76: 57064.87 | D76: =LN(B77/B76) -> 0.097299297 | E76: =LN(C77/C76) -> 0.020620979
A77: 44531 | B77: 1889.65 | C77: 58253.82 | D77: =LN(B78/B77) -> -0.084404866 | E77: =LN(C78/C77) -> -0.0041223786
A78: 44562 | B78: 1736.7 | C78: 58014.17 | D78: =LN(B79/B78) -> -0.011233471 | E78: =LN(C79/C78) -> -0.030929607
A79: 44593 | B79: 1717.3 | C79: 56247.28 | D79: =LN(B80/B79) -> 0.10488291 | E79: =LN(C80/C79) -> 0.040439496
A80: 44621 | B80: 1907.2 | C80: 58568.51 | D80: =LN(B81/B80) -> -0.19589905 | E80: =LN(C81/C80) -> -0.026078587
A81: 44652 | B81: 1567.9 | C81: 57060.87 | D81: =LN(B82/B81) -> -0.041642164 | E81: =LN(C82/C81) -> -0.026539711
... A123: 45931 | B123: 1482.5 | C123: 83938.71 | D123: =LN(B124/B123) -> 0.031537884 | E123: =LN(C124/C123) -> 0.0076938191
A124: 45962 | B124: 1530 | C124: 84587.01
G126: =AVERAGE(G4:G124) -> #DIV/0!

Sheet Beta_Calculations
A1: Beta Calculation
A2: Period | B2: Daily | C2: Weekly | D2: Monthly | G2: We use the 5-year monthly beta because it provides the most stable and reliable estimate of Infosys’ systematic risk. Monthly data smooths out daily market noise and reduces volatility distortions, while a 5-year horizon captures a full market cycle without including excessively old or structurally irrelevant information. This makes the 5-year monthly beta more appropriate for WACC estimation and long-term valuation.
A3: 5 Years | B3: =SLOPE(RawPrice_Daily!K4:K1243,RawPrice_Daily!L4:L1243) -> 0.96900415 | C3: =SLOPE(RawPrice_Weekly!K4:K258,RawPrice_Weekly!L4:L258) -> -0.042086233 | D3: =SLOPE(RawPrice_Monthly!K4:K64,RawPrice_Monthly!L4:L64) -> 0.90217395
A4: 10 Years | B4: =SLOPE(RawPrice_Daily!D4:D2478,RawPrice_Daily!E4:E2478) -> -0.0043684184 | C4: =SLOPE(RawPrice_Weekly!D4:D517,RawPrice_Weekly!E4:E517) -> 0.017434809 | D4: =SLOPE(RawPrice_Monthly!D4:D124,RawPrice_Monthly!E4:E124) -> 0.86302425
A6: Infosys
A7: Stastistics | B7: Daily | C7: Weekly | D7: Monthly
A8: Average | B8: =AVERAGE(RawPrice_Daily!I4:I1243) -> 1561.0238 | C8: =AVERAGE(RawPrice_Weekly!I4:I259) -> 1556.1139 | D8: =AVERAGE(RawPrice_Monthly!I4:I64) -> 1548.0926 | E8: 5 Years
A9: Standard Deviation | B9: =_xlfn.STDEV.S(RawPrice_Daily!I5:I1244) -> 189.20134 | C9: =_xlfn.STDEV.S(RawPrice_Weekly!I5:I260) -> 188.79401 | D9: =_xlfn.STDEV.S(RawPrice_Monthly!I5:I65) -> 181.63375
A11: Stastistics | B11: Daily | C11: Weekly | D11: Monthly | H11: A (Period) | I11: B (Beta)
A12: Average | B12: =AVERAGE(RawPrice_Daily!B4:B2479) -> 1251.6148 | C12: =AVERAGE(RawPrice_Weekly!B4:B518) -> 1095.5638 | D12: =AVERAGE(RawPrice_Monthly!B4:B124) -> 1251.1331 | E12: 10 Years | H12: 5 years - Daily | I12: =B3 -> 0.96900415
A13: Standard Deviation | B13: =_xlfn.STDEV.S(RawPrice_Daily!B5:B2480) -> 364.86796 | C13: =_xlfn.STDEV.S(RawPrice_Weekly!B5:B519) -> 488.44432 | D13: =_xlfn.STDEV.S(RawPrice_Monthly!B5:B125) -> 359.48972 | H13: 10 years - Daily | I13: =B4 -> -0.0043684184
H14: 5 years - Weekly | I14: =C3 -> -0.042086233
A15: Sensex | H15: 10 years - Weekly | I15: =C4 -> 0.017434809
A16: Stastistics | B16: Daily | C16: Weekly | D16: Monthly | H16: 5 years - Monhtly | I16: =D3 -> 0.90217395
A17: Average | B17: =AVERAGE(RawPrice_Daily!J13:J1252) -> 66022.196 | C17: =AVERAGE(RawPrice_Weekly!J13:IJ268) -> 19534.484 | D17: =AVERAGE(RawPrice_Monthly!J13:J73) -> 68645.574 | E17: 5 Years | H17: 10 years - Monthly | I17: =D4 -> 0.86302425
A18: Standard Deviation | B18: =_xlfn.STDEV.S(RawPrice_Daily!J14:J1253) -> 11125.747 | C18: =_xlfn.STDEV.S(RawPrice_Weekly!J4:IJ269) -> 28363.798 | D18: =_xlfn.STDEV.S(RawPrice_Monthly!J14:J74) -> 10022.259
A20: Stastistics | B20: Daily | C20: Weekly | D20: Monthly
A21: Average | B21: =AVERAGE(RawPrice_Daily!C13:C2488) -> 49716.299 | C21: =AVERAGE(RawPrice_Weekly!C13:C527) -> 49687.521 | D21: =AVERAGE(RawPrice_Monthly!C13:C133) -> 51606.281 | E21: 10 Years
A22: Standard Deviation | B22: =_xlfn.STDEV.S(RawPrice_Daily!C14:C2489) -> 18400.485 | C22: =_xlfn.STDEV.S(RawPrice_Weekly!C14:C528) -> 18119.467 | D22: =_xlfn.STDEV.S(RawPrice_Monthly!C14:C134) -> 17919.814
K25: “The regression line β = 0.0643x + 0.2259 shows a slight upward slope, indicating that Infosys’ beta has increased marginally across the different estimation windows (daily/weekly/monthly, 5-year and 10-year). However, the R² value is only 0.0565, which means the trend is extremely weak and the variation in beta is largely driven by estimation noise rather than a true structural change in risk. Therefore, beta appears to be stable, and using the most recent computed beta (0.90217) for CAPM and WACC is appropriate.”

Sheet Income_Statement
A1: Income Statement of Infosys
A2: Year | B2: Revenue | C2: Cost of Goods Sold | D2: Gross Profit | E2: Operating Expenses | F2: EBIT | G2: Interest Expense | H2: PBT | I2: Tax Expense | J2: Net Income | K2: Tax Rate | L2: (In Crores)
A3: 2015 | B3: 56749 | C3: 0 | D3: 56749 | E3: 39465 | F3: =B3-E3 -> 17284 | G3: 0 | H3: 17284 | I3: 4911 | J3: =H3-I3 -> 12373 | K3: =I3/H3 -> 0.28413562
A4: 2016 | B4: 65569 | C4: 0 | D4: 65569 | E4: 46587 | F4: 18982 | G4: 0 | H4: 18982 | I4: 5329 | J4: 13681 | K4: =I4/H4 -> 0.28073965
A5: 2017 | B5: 71564 | C5: 0 | D5: 71564 | E5: 51583 | F5: =B5-E5 -> 19981 | G5: 0 | H5: 19951 | I5: 5598 | J5: =H5-I5 -> 14353 | K5: =I5/H5 -> 0.28058744
A6: 2018 | B6: 73715 | C6: 0 | D6: 73715 | E6: 53374 | F6: 20341 | G6: 0 | H6: 20270 | I6: 4241 | J6: 16029 | K6: =I6/H6 -> 0.20922546
A7: 2019 | B7: 85557 | C7: 0 | D7: 85557 | E7: 64516 | F7: 21041 | G7: 0 | H7: 21041 | I7: 5631 | J7: 15410 | K7: =I7/H7 -> 0.26762036
A8: 2020 | B8: 93594 | C8: 0 | D8: 93594 | E8: 71587 | F8: 22007 | G8: 0 | H8: 22007 | I8: 5368 | J8: 16639 | K8: =I8/H8 -> 0.24392239
A9: 2021 | B9: 102673 | C9: 0 | D9: 102673 | E9: 76045 | F9: 26628 | G9: 0 | H9: 26628 | I9: 7205 | J9: 19423 | K9: =I9/H9 -> 0.27057984
A10: 2022 | B10: 123936 | C10: 0 | D10: 123936 | E10: 93826 | F10: 30110 | G10: 0 | H10: 30110 | I10: 7964 | J10: 22146 | K10: =I10/H10 -> 0.26449684
A11: 2023 | B11: 149468 | C11: 0 | D11: 149468 | E11: 116146 | F11: 33322 | G11: 0 | H11: 33322 | I11: 9214 | J11: 24108 | K11: =I11/H11 -> 0.27651401
A12: 2024 | B12: 158381 | C12: 0 | D12: 158381 | E12: 122393 | F12: 35988 | G12: 0 | H12: 35988 | I12: 9740 | J12: 26248 | K12: =I12/H12 -> 0.27064577
A13: 2025 | B13: 166590 | C13: 0 | D13: 166590 | E13: 128982 | F13: 37608 | G13: 0 | H13: 37608 | I13: 10858 | J13: 26750 | K13: =I13/H13 -> 0.28871517

Sheet Balance_Sheet
A1: Balace Sheet of Infosys
A2: Year | B2: Total Assets | C2: Current Assets | D2: Non-Current Assets | E2: Total Liabilities | F2: Current Liabilities | G2: Non-Current Liabilities | H2: Equity | I2: Cash | J2: Debt | K2: Accounts receivables | L2: (In Crores)
A3: 2015 | B3: 66289 | C3: 47242 | D3: 19047 | E3: 15553 | F3: 15503 | G3: 50 | H3: 50736 | I3: 30367 | J3: 0 | K3: 0
A4: 2016 | B4: 75141 | C4: 51753 | D4: 23388 | E4: 17315 | F4: 17189 | G4: 126 | H4: 57826 | I4: 32697 | J4: 0 | K4: 0
A5: 2017 | B5: 83355 | C5: 53705 | D5: 29650 | E5: 14373 | F5: 14013 | G5: 360 | H5: 68982 | I5: 22625 | J5: 0 | K5: 0
A6: 2018 | B6: 79890 | C6: 50017 | D6: 29873 | E6: =SUM(F6:G6) -> 14966 | F6: 14105 | G6: 861 | H6: 64924 | I6: 19818 | J6: 0 | K6: 0
A7: 2019 | B7: 84738 | C7: 52878 | D7: 31860 | E7: =SUM(F7:G7) -> 19732 | F7: 18638 | G7: 1094 | H7: 65006 | I7: 19568 | J7: 0 | K7: 0
A8: 2020 | B8: 92768 | C8: 54576 | D8: 38192 | E8: =SUM(F8:G8) -> 26924 | F8: 20856 | G8: 6068 | H8: 65844 | I8: 18649 | J8: 0 | K8: 18487
A9: 2021 | B9: 108386 | C9: 60733 | D9: 47653 | E9: 31604 | F9: 23865 | G9: 7739 | H9: 76782 | I9: 24714 | J9: 0 | K9: 19294
A10: 2022 | B10: 117885 | C10: 67185 | D10: 50700 | E10: =SUM(F10:G10) -> 42149 | F10: 33603 | G10: 8546 | H10: 75736 | I10: 17472 | J10: 0 | K10: 22698
A11: 2023 | B11: =SUM(C11:D11) -> 125816 | C11: 70881 | D11: 54935 | E11: =SUM(F11:G11) -> 50021 | F11: 39186 | G11: 10835 | H11: 75795 | I11: 12173 | J11: 0 | K11: 25424
A12: 2024 | B12: 137814 | C12: 89432 | D12: 48382 | E12: =10559+38794 -> 49353 | F12: 38794 | G12: 10559 | H12: 88461 | I12: 14786 | J12: 0 | K12: 30193
A13: 2025 | B13: 148903 | C13: 97099 | D13: 51804 | E13: =SUM(F13:G13) -> 52700 | F13: 42850 | G13: 9850 | H13: 96203 | I13: 24455 | J13: 0 | K13: 31158

Sheet Cash_Flow_Statement
A1: Cash Flow Statement of Infosys
A2: Year | B2: Net Income | C2: Depreciation | D2: Change in WC | E2: CFO | F2: CapEx | G2: CFI | H2: Dividends | I2: CFF | J2: Net Cash Flow | K2: (In Crores)
A3: 2015 | B3: 17283 | C3: 1017 | D3: -842 | E3: 15104 | F3: -2255 | G3: 1088 | H3: -4935 | I3: -4935 | J3: 30367
A4: 2016 | B4: 18979 | C4: 1266 | D4: -1946 | E4: 10028 | F4: -2723 | G4: -901 | H4: -6813 | I4: -6813 | J4: 32697
A5: 2017 | B5: 14353 | C5: 1703 | D5: -2156 | E5: 11531 | F5: -2760 | G5: -14542 | H5: -6939 | I5: -6939 | J5: 22625
A6: 2018 | B6: 16029 | C6: 1863 | D6: 84 | E6: 20047 | F6: -1998 | G6: 4452 | H6: -7464 | I6: -20505 | J6: 19871
A7: 2019 | B7: 15410 | C7: 2011 | D7: -453 | E7: 21673 | F7: -2445 | G7: -575 | H7: -13705 | I7: -14512 | J7: 19568
A8: 2020 | B8: 16639 | C8: 2893 | D8: -2367 | E8: 17003 | F8: -3307 | G8: -239 | H8: -9515 | I8: -17591 | J8: 18649
A9: 2021 | B9: 19423 | C9: 3267 | D9: 768 | E9: 23224 | F9: -2107 | G9: -7456 | H9: -9117 | I9: -9786 | J9: 24714
A10: 2022 | B10: 22146 | C10: 3476 | D10: -1424 | E10: 23885 | F10: 2161 | G10: 6416 | H10: 12652 | I10: 24642 | J10: 17472
A11: 2023 | B11: 24108 | C11: 4225 | D11: -6344 | E11: 22467 | F11: -2579 | G11: -1209 | H11: -13631 | I11: -26695 | J11: -12173
A12: 2024 | B12: 26248 | C12: 4678 | D12: -5092 | E12: 25210 | F12: -2201 | G12: -5009 | H12: -14692 | I12: -17504 | J12: 14786
A13: 2025 | B13: 26750 | C13: 4812 | D13: -647 | E13: 35694 | F13: -2237 | G13: -1946 | H13: -20287 | I13: -24161 | J13: 24455

Sheet Ratio_Analysis
A1: Financial Ratio Analysis of INFOSYS
A2: Year | B2: 2025 | C2: 2024 | D2: 2023 | E2: 2022 | F2: 2021
A3: Profitability Ratios
A4: Return on Capital | B4: =Income_Statement!F13/Balance_Sheet!H13 -> 0.39092336 | C4: =Income_Statement!F12/Balance_Sheet!H12 -> 0.40682335 | D4: =Income_Statement!F11/Balance_Sheet!H11 -> 0.43963322 | E4: =Income_Statement!F10/Balance_Sheet!H10 -> 0.39756523 | F4: =Income_Statement!F9/Balance_Sheet!H9 -> 0.34680003
A5: Return on Equity | B5: =Income_Statement!J13/Balance_Sheet!H13 -> 0.27805786 | C5: =Income_Statement!F12/Balance_Sheet!H12 -> 0.40682335 | D5: =Income_Statement!F11/Balance_Sheet!H11 -> 0.43963322 | E5: =Income_Statement!F10/Balance_Sheet!H10 -> 0.39756523 | F5: =Income_Statement!F9/Balance_Sheet!H9 -> 0.34680003
A6: EBIT Margin | B6: =Income_Statement!F13/Income_Statement!B13 -> 0.22575185 | C6: =Income_Statement!F12/Income_Statement!B12 -> 0.22722423 | D6: =Income_Statement!F11/Income_Statement!B11 -> 0.22293735 | E6: =Income_Statement!F10/Income_Statement!B10 -> 0.24294797 | F6: =Income_Statement!F9/Income_Statement!B9 -> 0.25934764
A7: Return on Asset | B7: =Income_Statement!J13/Balance_Sheet!B13 -> 0.17964715 | C7: =Income_Statement!J12/Balance_Sheet!B12 -> 0.1904596 | D7: =Income_Statement!J11/Balance_Sheet!B11 -> 0.19161315 | E7: =Income_Statement!J10/Balance_Sheet!B10 -> 0.18786105 | F7: =Income_Statement!J9/Balance_Sheet!B9 -> 0.17920211
A9: Liquidity Ratios
A10: Current Ratio | B10: =Balance_Sheet!C13/Balance_Sheet!F13 -> 2.266021 | C10: =Balance_Sheet!C12/Balance_Sheet!F12 -> 2.3053049 | D10: =Balance_Sheet!C11/Balance_Sheet!F11 -> 1.8088348 | E10: =Balance_Sheet!C10/Balance_Sheet!F10 -> 1.9993751 | F10: =Balance_Sheet!C9/Balance_Sheet!F9 -> 2.5448565
A11: Quick Ratio | B11: =Balance_Sheet!C13/Balance_Sheet!F13 -> 2.266021 | C11: =Balance_Sheet!C12/Balance_Sheet!F12 -> 2.3053049 | D11: =Balance_Sheet!C11/Balance_Sheet!F11 -> 1.8088348 | E11: =Balance_Sheet!C10/Balance_Sheet!F10 -> 1.9993751 | F11: =Balance_Sheet!C9/Balance_Sheet!F9 -> 2.5448565
A13: Leverage Ratios
A14: Assets/Equity(Equity Multiplier) | B14: =Balance_Sheet!B13/Balance_Sheet!H13 -> 1.5478 | C14: =Balance_Sheet!B12/Balance_Sheet!H12 -> 1.5579069 | D14: =Balance_Sheet!B11/Balance_Sheet!H11 -> 1.6599512 | E14: =Balance_Sheet!B10/Balance_Sheet!H10 -> 1.5565253 | F14: =Balance_Sheet!B9/Balance_Sheet!H9 -> 1.4116069
A15: Debt/Total Capital | B15: 0 | C15: 0 | D15: 0 | E15: 0 | F15: 0
A16: Interest Coverage | B16: 0 | C16: 0 | D16: 0 | E16: 0 | F16: 0
A17: Debt/Equity | B17: 0 | C17: 0 | D17: 0 | E17: 0 | F17: 0
A19: Activity Ratios
A20: Sales/Assets(Asset Turnover) | B20: =Income_Statement!J13/Balance_Sheet!B13 -> 0.17964715 | C20: =Income_Statement!J12/Balance_Sheet!B12 -> 0.1904596 | D20: =Income_Statement!J11/Balance_Sheet!B11 -> 0.19161315 | E20: =Income_Statement!J10/Balance_Sheet!B10 -> 0.18786105 | F20: =Income_Statement!J9/Balance_Sheet!B9 -> 0.17920211
A21: Average Daily Sales | B21: =Cash_Flow_Statement!B13/365 -> 73.287671 | C21: =Cash_Flow_Statement!B12/365 -> 71.912329 | D21: =Cash_Flow_Statement!B11/365 -> 66.049315 | E21: =Cash_Flow_Statement!B10/365 -> 60.673973 | F21: =Cash_Flow_Statement!B9/365 -> 53.213699
A22: Days Receivables | B22: =(Balance_Sheet!K13/Income_Statement!B13)*365 -> 68.267423 | C22: =(Balance_Sheet!K12/Income_Statement!B12)*365 -> 69.581863 | D22: =(Balance_Sheet!K11/Income_Statement!B11)*365 -> 62.085262 | E22: =(Balance_Sheet!K10/Income_Statement!B10)*365 -> 66.847163 | F22: =(Balance_Sheet!K9/Income_Statement!B9)*365 -> 68.589697
A24: YoY Growth
A25: Revenue Growth | B25: =(Income_Statement!B13-Income_Statement!B12)/Income_Statement!B12 -> 0.051830712 | C25: =(Income_Statement!B12-Income_Statement!B11)/Income_Statement!B11 -> 0.059631493 | D25: =(Income_Statement!B11-Income_Statement!B10)/Income_Statement!B10 -> 0.20600955 | E25: =(Income_Statement!B10-Income_Statement!B9)/Income_Statement!B9 -> 0.20709437 | F25: =(Income_Statement!B9-Income_Statement!B8)/Income_Statement!B8 -> 0.097004081
B30: (1) Debt-related ratios are reported as zero because Infosys carries no interest-bearing debt during the financial years presented. Consequently, Debt/Total Capital, Debt/Equity, and Interest Coverage all equal zero.
B31: (2) Infosys operates with no inventory, consistent with IT services business models. Therefore the Quick Ratio equals the Current Ratio, as inventory is not a component of current assets.
B32: (3) Reported YoY Growth values correspond directly to annual Revenue Growth calculations for each fiscal year.

Sheet WACC
A1: WACC of Infosys
A3: Risk-free rate (Rf) | B3: 0.06527
A4: Market Risk Premium (MRP) | B4: =RawPrice_Monthly!T4-B3 -> 0.064317494
A5: Beta | B5: 0.90217395
A6: Cost of Equity: Ke = Rf + Beta * MRP | B6: =B3+Beta_Calculations!D3*(WACC!B4) -> 0.12329557
A7: Cost of Debt (Kd) | B7: -
A8: Tax Rate | B8: =Income_Statement!I13/Income_Statement!H13 -> 0.28871517
A9: Market value of Equity (E) | B9: =Dividend_Analysis!B12*Dividend_Analysis!G12 -> 6244920000000
A10: Market value of Debt (D) | B10: -
A11: V = E + D | B11: =B9 -> 6244920000000
A12: WACC | B12: =B6 -> 0.12329557
A18: (1) Infosys has no interest-bearing debt outstanding during the period considered. As a result, the Cost of Debt (Kd), Market Value of Debt (D), and the debt component in the WACC formula are treated as zero.
A19: (2) Because the capital structure consists entirely of equity (D = 0), the total firm value (V) equals the Market Value of Equity (E). Thus, the WACC is equivalent to the Cost of Equity.
A20: (3) The Cost of Equity (Ke) is calculated using the Capital Asset Pricing Model (CAPM):
A21: Ke = Rf + β × MRP,
A22: where Rf is the risk-free rate, β is Infosys’ equity beta, and MRP is the Market Risk Premium.
A23: (4) Tax rate is provided but has no effect on WACC in this case because there is no debt component requiring a tax-adjusted cost.
A24: (5) Market Value of Equity is based on the company’s market capitalization at the measurement date.

Sheet Cash_Flow_Analysis
A1: Cash Flow Analysis of Infosys
J3: Depriciation | K3: Changes in WC | L3: Cap Ex | M3: Revenue | N3: WC as % of Revenue | O3: Tax Rate
I4: 2021 | J4: 3267 | K4: 768 | L4: -2107 | M4: 102673 | N4: =K4/M4 -> 0.007480058 | O4: 0.27057984
C5: 2025 | D5: 2024 | E5: 2023 | F5: 2022 | G5: 2021 | I5: 2022 | J5: 3476 | K5: -1424 | L5: 2161 | M5: 123936 | N5: =K5/M5 -> -0.011489801 | O5: 0.26449684
B6: Growth rates | C6: 0.051830712 | D6: 0.059631493 | E6: 0.20600955 | F6: 0.20709437 | G6: 0.097004081 | I6: 2023 | J6: 4225 | K6: -6344 | L6: -2579 | M6: 149468 | N6: =K6/M6 -> -0.042443868 | O6: 0.27651401
I7: 2024 | J7: 4678 | K7: -5092 | L7: -2201 | M7: 158381 | N7: =K7/M7 -> -0.032150321 | O7: 0.27064577
B8: EBIT Margin | C8: 0.22575185 | D8: 0.22722423 | E8: 0.22293735 | F8: 0.24294797 | G8: 0.25934764 | I8: 2025 | J8: 4812 | K8: -647 | L8: -2237 | M8: 166590 | N8: =K8/M8 -> -0.0038837865 | O8: 0.28871517
A12: Base FCF growth rate(CAGR) | B12: =(G30/G26)^(1/4)-1 -> 0.080503611
A13: wacc | B13: 0.1233
C17: NOPAT | D17: FCFF
B18: 2021 | C18: =Income_Statement!F9*(1-Cash_Flow_Analysis!O4) -> 19423 | D18: =C18+J4-L4-N4 -> 24796.993
B19: 2022 | C19: =Income_Statement!F10*(1-Cash_Flow_Analysis!O5) -> 22146 | D19: =C19+J5-L5-N5 -> 23461.011 | E19: =D18*(1+$F$6)/(WACC!$B$12-Cash_Flow_Analysis!F6) -> -357192.59
B20: 2023 | C20: =Income_Statement!F11*(1-Cash_Flow_Analysis!O6) -> 24108 | D20: =C20+J6-L6-N6 -> 30912.042 | E20: =D19*(1+$F$6)/(WACC!$B$12-E6) -> -342380.49
B21: 2024 | C21: =Income_Statement!F12*(1-Cash_Flow_Analysis!O7) -> 26248 | D21: =C21+J7-L7-N7 -> 33127.032 | E21: =D20*(1+$F$6)/(WACC!$B$12-D6) -> 586103.74
B22: 2025 | C22: =Income_Statement!F13*(1-Cash_Flow_Analysis!O8) -> 26750 | D22: =C22+J8-L8-N8 -> 33799.004 | E22: =D21*(1+$F$6)/(WACC!$B$12-C6) -> 559540.12
B25: Historical data | C25: Year | D25: Operating CF | E25: Investing CF | F25: Financing CF | G25: Free Cash Flow | H25: Net Income
C26: 2021 | D26: 23224 | E26: -7456 | F26: -9786 | G26: 24796.993 | H26: 19423
C27: 2022 | D27: 23885 | E27: -6416 | F27: -24642 | G27: 23461.011 | H27: 22146
C28: 2023 | D28: 22467 | E28: -1209 | F28: -26695 | G28: 30912.042 | H28: 24108
C29: 2024 | D29: 25210 | E29: -5009 | F29: -17504 | G29: 33127.032 | H29: 26248
C30: 2025 | D30: 35694 | E30: -1946 | F30: -24161 | G30: 33799.004 | H30: 26750
B36: Projection | C36: Year | D36: Projected Operating CF | E36: Projected Investing CF | F36: Projected Financing CF | G36: Projected Free Cash Flow | H36: Discount Factor | I36: PV of Cash Flow
C37: 2026 | D37: =D30*(1+$B$12) -> 38567.496 | E37: =E30*(1+$B$12) -> -2102.66 | F37: =F30*(1+$B$12) -> -26106.048 | G37: =G30*(1+$B$12) -> 36519.946 | H37: =1/(1+$B$13) -> 0.89023413 | I37: =G37*H37 -> 32511.302
C38: 2027 | D38: =D37*(1+$B$12) -> 41672.319 | E38: =E37*(1+$B$12) -> -2271.9318 | F38: =F37*(1+$B$12) -> -28207.679 | G38: =G37*(1+$B$12) -> 39459.933 | H38: =1/(1+$B$13)^2 -> 0.79251681 | I38: =G38*H38 -> 31272.66
C39: 2028 | D39: =D38*(1+$B$12) -> 45027.091 | E39: =E38*(1+$B$12) -> -2454.8305 | F39: =F38*(1+$B$12) -> -30478.499 | G39: =G38*(1+$B$12) -> 42636.6 | H39: =1/(1+$B$13)^3 -> 0.70552551 | I39: =G39*H39 -> 30081.209
C40: 2029 | D40: =D39*(1+$B$12) -> 48651.934 | E40: =E39*(1+$B$12) -> -2652.4532 | F40: =F39*(1+$B$12) -> -32932.128 | G40: =G39*(1+$B$12) -> 46069.001 | H40: =1/(1+$B$13)^4 -> 0.62808289 | I40: =G40*H40 -> 28935.151
C41: 2030 | D41: =D40*(1+$B$12) -> 52568.59 | E41: =E40*(1+$B$12) -> -2865.9852 | F41: =F40*(1+$B$12) -> -35583.283 | G41: =G40*(1+$B$12) -> 49777.722 | H41: =1/(1+$B$13)^5 -> 0.55914083 | I41: =G41*H41 -> 27832.756
A48: (1) Depreciation, Working Capital changes, Capital Expenditure, and Revenue figures are based on historical financial statements of Infosys for FY 2021–2025.
A49: (2) Working Capital as a percentage of revenue shows negative values in some years due to decreases in net working capital, which result in positive cash flow contributions (i.e., WC release).
A50: (3) EBIT Margin values are used in NOPAT calculations, which feed into Free Cash Flow to Firm (FCFF) computations.
A51: (4) NOPAT is calculated as:
A52: NOPAT = EBIT × (1 − Tax Rate)
A53: The tax rates used correspond to each specific year as shown in the sheet.
A54: (5) FCFF is derived using the formula:
A55: FCFF = NOPAT + Depreciation − Capital Expenditure − Changes in Working Capital
A56: Positive FCFF indicates available free cash flow for investors; negative values reflect large reinvestment years.
A57: (6) Historical Operating, Investing, and Financing Cash Flow values correspond to Infosys’ published cash flow statements. Free Cash Flow shown in the historical section reconciles directly with FCFF.
A58: (7) Projection years (2026–2030) assume stable cash flows based on FY 2025 levels, unless noted otherwise. These projections illustrate the continuation of operating performance under constant growth conditions.
A59: (8) Discount factors are computed using the Weighted Average Cost of Capital (WACC) of 12.33% derived earlier:
... A70: Using 2025 FCF = 33,799

Sheet Investment_Analysis
A1: Investment Analysis of Infosys
A3: Label | B3: Value
A4: Initial Investment | B4: 256
A5: WACC (discount rate) | B5: 0.1233
A6: Project Life | B6: 10
A7: Revenue Year 1 | B7: 400
A8: Revenue Growth | B8: 0.0518 | E8: 0 | F8: 1 | G8: 2 | H8: 3 | I8: 4 | J8: 5 | K8: 6 | L8: 7 | M8: 8 | N8: 9 | O8: 10
A9: Operating Margin | B9: 0.211 | D9: Initial Investment | E9: =-B4 -> -256
A10: Tax Rate | B10: 0.289 | D10: Savings | F10: =B7 -> 400 | G10: =B7*(1+$B$8) -> 420.72 | H10: =G10*(1+$B$8) -> 442.5133 | I10: =H10*(1+$B$8) -> 465.43548 | J10: =I10*(1+$B$8) -> 489.54504 | K10: =J10*(1+$B$8) -> 514.90348 | L10: =K10*(1+$B$8) -> 541.57548 | M10: =L10*(1+$B$8) -> 569.62909 | N10: =M10*(1+$B$8) -> 599.13587 | O10: =N10*(1+$B$8) -> 630.17111
D11: EBIT | F11: =F10*$B$9 -> 84.4 | G11: =G10*$B$9 -> 88.77192 | H11: =H10*$B$9 -> 93.370305 | I11: =I10*$B$9 -> 98.206887 | J11: =J10*$B$9 -> 103.294 | K11: =K10*$B$9 -> 108.64463 | L11: =L10*$B$9 -> 114.27243 | M11: =M10*$B$9 -> 120.19174 | ... O11: =O10*$B$9 -> 132.9661
D12: Tax | F12: =F11*$B$10 -> 24.3916 | G12: =G11*$B$10 -> 25.655085 | H12: =H11*$B$10 -> 26.984018 | I12: =I11*$B$10 -> 28.38179 | J12: =J11*$B$10 -> 29.851967 | K12: =K11*$B$10 -> 31.398299 | L12: =L11*$B$10 -> 33.024731 | M12: =M11*$B$10 -> 34.735412 | ... O12: =O11*$B$10 -> 38.427204
D13: Operating | F13: =F11-F12 -> 60.0084 | G13: =G11-G12 -> 63.116835 | H13: =H11-H12 -> 66.386287 | I13: =I11-I12 -> 69.825097 | J13: =J11-J12 -> 73.442037 | K13: =K11-K12 -> 77.246334 | L13: =L11-L12 -> 81.247695 | M13: =M11-M12 -> 85.456325 | ... O13: =O11-O12 -> 94.5389
D14: Depriciation | F14: =$B$4/$B$6 -> 25.6 | G14: =$B$4/$B$6 -> 25.6 | H14: =$B$4/$B$6 -> 25.6 | I14: =$B$4/$B$6 -> 25.6 | J14: =$B$4/$B$6 -> 25.6 | K14: =$B$4/$B$6 -> 25.6 | L14: =$B$4/$B$6 -> 25.6 | M14: =$B$4/$B$6 -> 25.6 | ... O14: =$B$4/$B$6 -> 25.6
D15: FCF | E15: -256 | F15: =F13+F14 -> 85.6084 | G15: =G13+G14 -> 88.716835 | H15: =H13+H14 -> 91.986287 | I15: =I13+I14 -> 95.425097 | J15: =J13+J14 -> 99.042037 | K15: =K13+K14 -> 102.84633 | L15: =L13+L14 -> 106.84769 | M15: =M13+M14 -> 111.05633 | ... O15: =O13+O14 -> 120.1389
G18: =NPV(B5,F15:O15) -> 547.20032
F19: NPV | G19: =G18+E9 -> 291.20032
F21: IRR | G21: =IRR(E15:O15) -> 0.3472573
F22: PI | G22: =G19/B4 -> 1.1375012
A27: (1) Initial Investment of ₹256 is treated as a cash outflow at Year 0 and forms the basis for NPV, IRR, and Free Cash Flow calculations.
A28: (2) Revenue is projected using a constant annual growth rate of 5%, applied multiplicatively each year:
A29: Revenueₜ = Revenueₜ₋₁ × (1 + Growth Rate).
A30: (3) EBIT is calculated using the Operating Margin of 21.1% applied to revenue for each projected year:
A31: EBIT = Revenue × Operating Margin.
A32: (4) Tax expense is based on the assumed corporate tax rate of 28.9%, applied to EBIT:
A33: Tax = EBIT × Tax Rate.
A34: (5) Operating Income (Net Operating Profit After Tax – NOPAT) is computed as:
A35: Operating Income = EBIT − Tax.
A36: (6) Depreciation is assumed to be constant at ₹25.6 each year for simplicity. This acts as a non-cash expense added back when computing Free Cash Flow.
A37: (7) Free Cash Flow (FCF) is calculated as:
A38: FCF = Operating Income + Depreciation
... A43: (11) All figures are denominated in ₹ (Indian Rupees), and rounding may cause minor deviations when manually reconciling values.

Sheet Dividend_Analysis
A1: Dividend Analysis of Infosys
A2: Date | B2: No. of Shares | C2: Dividend (per share) | D2: Total Dividend | E2: Net Profit | F2: Dividend Payout | G2: Share Price | H2: Dividend Yield
A3: 44347 | B3: 4190000000 | C3: 15 | D3: =B3*C3 -> 62850000000 | E3: 194230000000 | F3: =D3/E3 -> 0.32358544 | G3: 1393.65 | H3: =C3/G3 -> 0.010763104
A4: 44495 | B4: 4190000000 | C4: 15 | D4: =B4*C4 -> 62850000000 | E4: 194230000000 | F4: =D4/E4 -> 0.32358544 | G4: 1704.1 | H4: =C4/G4 -> 0.0088023003
A5: 44712 | B5: 4210000000 | C5: 16 | D5: =B5*C5 -> 67360000000 | E5: 221460000000 | F5: =D5/E5 -> 0.30416328 | G5: 1503.95 | H5: =C5/G5 -> 0.010638652
A6: 44861 | B6: 4210000000 | C6: 16.5 | D6: =B6*C6 -> 69465000000 | E6: 221460000000 | F6: =D6/E6 -> 0.31366838 | G6: 1522.6 | H6: =C6/G6 -> 0.010836727
A7: 45079 | B7: 4140000000 | C7: 17.5 | D7: =B7*C7 -> 72450000000 | E7: 241080000000 | F7: =D7/E7 -> 0.30052265 | G7: 1298.65 | H7: =C7/G7 -> 0.013475532
A8: 45224 | B8: 4140000000 | C8: 18 | D8: =B8*C8 -> 74520000000 | E8: 241080000000 | F8: =D8/E8 -> 0.30910901 | G8: 1370.1 | H8: =C8/G8 -> 0.013137727
A9: 45443 | B9: 4140000000 | C9: 20 | D9: =B9*C9 -> 82800000000 | E9: 262480000000 | F9: =D9/E9 -> 0.31545261 | G9: 1406.25 | H9: =C9/G9 -> 0.014222222
A10: 45594 | B10: 4140000000 | C10: 21 | D10: =B10*C10 -> 86940000000 | E10: 262480000000 | F10: =D10/E10 -> 0.33122524 | G10: 1838.75 | H10: =C10/G10 -> 0.011420802
A11: 45807 | B11: 4150000000 | C11: 22 | D11: =B11*C11 -> 91300000000 | E11: 267500000000 | F11: =D11/E11 -> 0.34130841 | G11: 1562.8 | H11: =C11/G11 -> 0.014077297
A12: 45957 | B12: 4150000000 | C12: 23 | D12: =B12*C12 -> 95450000000 | E12: 267500000000 | F12: =D12/E12 -> 0.35682243 | G12: 1504.8 | H12: =C12/G12 -> 0.015284423
G15: Retention Ratio | H15: =(E12-D12)/E12 -> 0.64317757 | J15: Retention Ratio = (Net Income - Dividend Paid)/ Net Income
G16: g = Retention Ratio (ROE)
G17: =H15*Ratio_Analysis!B5 -> 0.17884058
G19: Dividend Growth Model (RE = (D1/Po)+g) | J19: D1 | K19: =C12*(1+G17) -> 27.113333
G20: =(K19/G12)+G17 -> 0.19685847
G21: Capital Assest Pricing Model ( Re = Rf + B(Rm-Rf))
G22: =0.0653 + (Beta_Calculations!D3*0.0643) -> 0.12330978
G24: As the Dividends distributed are not stable so we will preffer CAPM Model
U27: AQAAWQ
A29: (1) Dividend payout is calculated as Total Dividend ÷ Net Profit for each distribution period.
A30: (2) Dividend yield is computed as Dividend per Share ÷ Share Price on the declaration date.
A31: (3) Share counts change slightly over time due to buybacks or ESOP issuances.
A32: (4) Dividend growth is not stable across years; therefore, the Gordon Growth Model is less reliable and CAPM is preferred for estimating the cost of equity.
A33: (5) All monetary values are in ₹ (Indian Rupees), and rounding may cause minor variation
K37: A

Sheet Working_Capital
A1: Working Capital Management of Infosys
B3: Beginning (in crores) | C3: Ending(in crores)
A4: Inventory | B4: 0 | C4: 0
A5: Accounts Payable | B5: 4361 | C5: 4549
A6: Accounts Receivable | B6: 30193 | C6: 31158
A8: Sales | B8: 166590
A9: Cost of Sales | B9: 113347
A10: Cost of Goods Sold | B10: -
A12: Average Accounts Payable | B12: =AVERAGE(B5:C5) -> 4455
A13: Average Accounts Receivable | B13: =AVERAGE(B6:C6) -> 30675.5
A15: Inventory Period (avg inv/COGS * 365) | B15: 0
A16: Accounts Receivable Period (avg rec/sales * 365) | B16: =(B13/B8)*365 -> 67.210262
A17: Accounts Payable Period (avg pay/sales * 365) | B17: =(B12/B9)*365 -> 14.345991
A19: Operating Cycle | B19: =B15+B16 -> 67.210262
A20: Cash Cycle | B20: =B16-B17 -> 52.864271
A21: Net Working Capital (CA-CL) | B21: =Balance_Sheet!C13-Balance_Sheet!F13 -> 54249
A25: *All the calculations are for the year 2024-25
A28: (1) Inventory levels are zero because Infosys operates as an IT services company and does not maintain physical inventory.
A29: (2) Average receivables and payables are calculated using the beginning and ending balances for FY 2024–25.
A30: (3) Operating Cycle = Inventory Period + Accounts Receivable Period.
A31: (4) Cash Conversion Cycle = Operating Cycle − Accounts Payable Period.
A32: (5) Net Working Capital represents Current Assets minus Current Liabilities for the selected year.
A33: (6) All calculations are based on financial data for FY 2024–25 and values are presented in ₹ crores.

Sheet Charts_Dashboard
A1: Comprehensive Corporate Finance Evaluation Dashboard of Infosys Ltd.

Sheet DataSources_and_Checks
A1: Arithmetic Return: =(B3 - B2)/B2
A3: Log Return: =LN(B3/B2)
A7: Covariance Beta: =COVARIANCE.P(InfoReturnsRange, IndexReturnsRange)/VAR.P(IndexReturnsRange)
A9: CAPM: =Rf + Beta * MRP
A11: WACC: =(E/V)*Ke + (D/V)*Kd*(1-T)
A13: NOPAT: =EBIT*(1-T)
C14: Beta (SLOPE): =SLOPE(InfoReturnsRange, IndexReturnsRange)
A15: FCFF: =NOPAT + Depreciation - CapEx - ΔWC
A17: Terminal Value: =FCFFn*(1+g)/(WACC - g)
A19: Enterprise Value (NPV): =NPV(WACC,FCFF1:FCFFn) + TV/(1+WACC)^n
A21: Equity Value: =EnterpriseValue - NetDebt
A23: Per share: =EquityValue / SharesOutstanding
